Using TensorFlow backend.
Traceback (most recent call last):
  File "main.py", line 77, in <module>
    results = fit_evaluate(model, x_train_, y_train_, x_test, y_test, batch_size, epochs, lr, logstring=F'tb_logs/{modelpath}')
  File "/home/schestag/alphaProject/src/model_v3/fit_evaluate.py", line 21, in fit_evaluate
    callbacks = [tbCallBack])
  File "/home/schestag/miniconda3/envs/test/lib/python3.6/site-packages/keras/engine/training.py", line 952, in fit
    batch_size=batch_size)
  File "/home/schestag/miniconda3/envs/test/lib/python3.6/site-packages/keras/engine/training.py", line 789, in _standardize_user_data
    exception_prefix='target')
  File "/home/schestag/miniconda3/envs/test/lib/python3.6/site-packages/keras/engine/training_utils.py", line 138, in standardize_input_data
    str(data_shape))
ValueError: Error when checking target: expected varkeys_1 to have shape (3,) but got array with shape (10,)
srun: error: gpu-000: task 0: Exited with exit code 1
